# **Testando falhas**

* Erros nem sempre são inesperados;
* O Python utiliza exceções para sinalizar erros na execução e que nem sempre são fatais;
* Há testes que verificam que um erro deve ocorrer a partir de uma determinada entrada.

~~~py
# codigo.py
# ...

def divide(a_number, other_number):
    "Retorna a divisão de a_number por other_number"
    return a_number / other_number

# test_codigo.py
import pytest
from codigo import is_odd, divide

# ...

def test_divide_when_other_number_is_zero_raises_an_exception():
    with pytest.raises(ZeroDivisionError, match="division by zero"):
        divide(2, 0)
~~~

## **Função raises da pytest**

* Verifica se a exceção ocorreu;
* No caso negativo, lança um `AssertionError`, indicando que o teste não passou;
* Há como verificar também se o texto retornado na exceção é o esperado com `match`;
* `match` pode receber uma expressão regular;
* No exemplo, uma divisão por zero lança a exceção esperada e o teste passa com sucesso.
